Workbook

Sheet Cover
B1: RUBRIK, INC. (NYSE: RBRK) | DCF VALUATION
B2: UofT Decision Systems | Fundamental Research
B4: COMPANY OVERVIEW | G4: VALUATION FOOTBALL FIELD ($ / SHARE)
B5: Company: | C5: Rubrik, Inc. | G5: Method | H5: Low | I5: High | J5: Midpoint | K5: chart helper
B6: Ticker: | C6: NYSE: RBRK | G6: 52-Week Trading Range (at 5/12/2026) | H6: =DCF!C59 -> 42.25 | I6: =DCF!D59 -> 103 | J6: =AVERAGE(H6:I6) -> 72.625 | K6: =H6 -> 42.25 | L6: =I6-H6 -> 60.75 | M6: =TEXT(H6,"$0") -> $42 | N6: =TEXT(I6,"$0") -> $103 | O6: 52-Week Range
B7: Sector: | C7: Cybersecurity / Cloud Software | G7: DCF - Perpetuity Growth (WACC / g) | H7: =DCF!C60 -> 66.307099 | I7: =DCF!D60 -> 99.708858 | J7: =AVERAGE(H7:I7) -> 83.007978 | K7: =H7 -> 66.307099 | L7: =I7-H7 -> 33.401758 | M7: =TEXT(H7,"$0") -> $66 | N7: =TEXT(I7,"$0") -> $100 | O7: DCF - Perpetuity
B8: Fiscal Year End: | C8: January 31 | G8: DCF - Exit Multiple (9x - 13x) | H8: =DCF!C61 -> 70.405198 | I8: =DCF!D61 -> 83.232319 | J8: =AVERAGE(H8:I8) -> 76.818758 | K8: =H8 -> 70.405198 | L8: =I8-H8 -> 12.827121 | M8: =TEXT(H8,"$0") -> $70 | N8: =TEXT(I8,"$0") -> $83 | O8: DCF - Exit Multiple
B9: Valuation Date: | C9: May 12, 2026 | G9: Current Share Price | H9: =C14 -> 60.47 | K9: =C14-0.4 -> 60.07 | L9: 0.8 | M9: ="Current $"&TEXT(C14,"0.00") -> Current $60.47 | O9: Current Price
B10: Currency: | C10: USD ($000 except per-share data)
B11: Analyst: | C11: Bosco Yu
B13: INVESTMENT SUMMARY
B14: Current Share Price (5/12/2026) | C14: =WACC!C15 -> 60.47
B15: Target Price (weighted) | C15: =E31 -> 78.224237
B16: Implied Upside / (Downside) | C16: =C15/C14-1 -> 0.29360405
B17: Implied Rating | C17: =IF(C16>=0.15,"BUY",IF(C16<=-0.15,"SELL","HOLD")) -> BUY
B19: KEY ASSUMPTIONS
B20: WACC | C20: =WACC!C24 -> 0.096571991
B21: Terminal Growth Rate | C21: =DCF!C25 -> 0.025
B22: Exit EV / EBITDA Multiple | C22: =DCF!E29 -> 11
B23: Revenue CAGR (FY2026A - FY2040E) | C23: =(IS!T5/IS!F5)^(1/14)-1 -> 0.13876619
B24: Terminal Value % of Enterprise Value | C24: =DCF!C27/DCF!C32 -> 0.49252145
B25: Diluted Shares Outstanding (000) | C25: =WACC!C16 -> 228395.42
B27: TARGET PRICE WEIGHTING
B28: Method | C28: Implied Price | D28: Weight | E28: Contribution
B29: DCF - Perpetuity Growth | C29: =DCF!C39 -> 79.629715 | D29: 0.5 | E29: =C29*D29 -> 39.814857
B30: DCF - Exit Multiple | C30: =DCF!E39 -> 76.818758 | D30: 0.5 | E30: =C30*D30 -> 38.409379
B31: Weighted Target Price | D31: =SUM(D29:D30) -> 1 | E31: =SUM(E29:E30) -> 78.224237
B34: Model conventions: blue = hardcoded input | black = formula | green = link to another tab
B35: UofT Decision Systems - Fundamental Research. For educational purposes only; not investment advice.

Sheet IS
B1: INCOME STATEMENT ($000)
C2: FY2023 | D2: FY2024 | E2: FY2025 | F2: FY2026 | G2: FY2027E | H2: FY2028E | I2: FY2029E | J2: FY2030E | K2: FY2031E | L2: FY2032E | M2: FY2033E | N2: FY2034E | O2: FY2035E | P2: FY2036E | Q2: FY2037E | R2: FY2038E | S2: FY2039E | T2: FY2040E
B3: REVENUE
B4: Revenue | C4: 599819 | D4: 627892 | E4: 886544 | F4: 1316191 | G4: =F4*(1+G40) -> 1750534 | H4: =G4*(1+H40) -> 2240683.6 | I4: =H4*(1+I40) -> 2800854.4 | J4: =I4*(1+J40) -> 3417042.4 | K4: =J4*(1+K40) -> 4066280.5 | L4: =K4*(1+L40) -> 4716885.4 | M4: =L4*(1+M40) -> 5330080.5 | N4: =M4*(1+N40) -> 5863088.5 | ... T4: =S4*(1+T40) -> 8117136.3
B5: Total Revenue | C5: =SUM(C4:C4) -> 599819 | D5: =SUM(D4:D4) -> 627892 | E5: =SUM(E4:E4) -> 886544 | F5: =SUM(F4:F4) -> 1316191 | G5: =SUM(G4) -> 1750534 | H5: =SUM(H4) -> 2240683.6 | I5: =SUM(I4) -> 2800854.4 | J5: =SUM(J4) -> 3417042.4 | K5: =SUM(K4) -> 4066280.5 | L5: =SUM(L4) -> 4716885.4 | M5: =SUM(M4) -> 5330080.5 | N5: =SUM(N4) -> 5863088.5 | ... T5: =SUM(T4) -> 8117136.3
B6: Revenue Growth YoY | C6: __ | D6: =D5/C5-1 -> 0.046802452 | E6: =E5/D5-1 -> 0.41193708 | F6: =F5/E5-1 -> 0.48463133 | G6: =G5/F5-1 -> 0.33 | H6: =H5/G5-1 -> 0.28 | I6: =I5/H5-1 -> 0.25 | J6: =J5/I5-1 -> 0.22 | K6: =K5/J5-1 -> 0.19 | ... T6: =T5/S5-1 -> 0.035
B8: COST OF REVENUE
B9: Cost of Revenue | C9: 182014 | D9: 144962 | E9: 265748 | F9: 261877 | G9: =G5*(1-G32) -> 350106.81 | H9: =H5*(1-H32) -> 436933.29 | I9: =I5*(1-I32) -> 532162.35 | J9: =J5*(1-J32) -> 632152.85 | K9: =K5*(1-K32) -> 731930.49 | L9: =L5*(1-L32) -> 849039.37 | M9: =M5*(1-M32) -> 959414.48 | N9: =N5*(1-N32) -> 1055355.9 | ... T9: =T5*(1-T32) -> 1461084.5
B10: Gross Profit | C10: =C5-C9 -> 417805 | D10: =D5-D9 -> 482930 | E10: =E5-E9 -> 620796 | F10: =F5-F9 -> 1054314 | G10: =G5-G9 -> 1400427.2 | H10: =H5-H9 -> 1803750.3 | I10: =I5-I9 -> 2268692.1 | J10: =J5-J9 -> 2784889.6 | ... T10: =T5-T9 -> 6656051.7
B11: Gross Margin % | C11: =C10/C5 -> 0.69655179 | D11: =D10/D5 -> 0.76912909 | E11: =E10/E5 -> 0.70024274 | F11: =F10/F5 -> 0.8010342 | G11: =G10/G5 -> 0.8 | H11: =H10/H5 -> 0.805 | I11: =I10/I5 -> 0.81 | J11: =J10/J5 -> 0.815 | ... T11: =T10/T5 -> 0.82
B13: OPERATING EXPENSES
B14: Research & Development | C14: 175057 | D14: 206527 | E14: 531615 | F14: 373682 | G14: =G5*G33 -> 560170.89 | H14: =H5*H33 -> 672205.07 | I14: =I5*I33 -> 784239.25 | J14: =J5*J33 -> 888431.03 | K14: =K5*K33 -> 975907.32 | L14: =L5*L33 -> 1084883.6 | M14: =M5*M33 -> 1199268.1 | N14: =N5*N33 -> 1289879.5 | ... T14: =T5*T33 -> 1623427.3
B15: Sales & Marketing | C15: 417542 | D15: 482532 | E15: 867518 | F15: 769019 | G15: =G5*G34 -> 962793.72 | H15: =H5*H34 -> 1075528.1 | I15: =I5*I34 -> 1120341.8 | J15: =J5*J34 -> 1195964.8 | K15: =K5*K34 -> 1301209.8 | L15: =L5*L34 -> 1438650 | M15: =M5*M34 -> 1545723.3 | N15: =N5*N34 -> 1641664.8 | ... T15: =T5*T34 -> 2029284.1
B16: General & Administrative | C16: 86754 | D16: 100377 | E16: 355695 | F16: 257029 | G16: =G5*G35 -> 210064.08 | H16: =H5*H35 -> 224068.36 | I16: =I5*I35 -> 280085.44 | J16: =J5*J35 -> 273363.39 | K16: =K5*K35 -> 304971.04 | L16: =L5*L35 -> 330181.98 | M16: =M5*M35 -> 346455.23 | N16: =N5*N35 -> 351785.31 | ... T16: =T5*T35 -> 487028.18
B17: Total Operating Expenses | C17: =SUM(C14:C16) -> 679353 | D17: =SUM(D14:D16) -> 789436 | E17: =SUM(E14:E16) -> 1754828 | F17: =SUM(F14:F16) -> 1399730 | G17: =SUM(G14:G16) -> 1733028.7 | H17: =SUM(H14:H16) -> 1971801.5 | I17: =SUM(I14:I16) -> 2184666.5 | J17: =SUM(J14:J16) -> 2357759.3 | ... T17: =SUM(T14:T16) -> 4139739.5
B19: EBITDA | C19: =C22+C21 -> -239182 | D19: =D22+D21 -> -282201 | E19: =E22+E21 -> -1105164 | F19: =F22+F21 -> -308301 | G19: =G22+G21 -> -287087.58 | H19: =H22+H21 -> -118756.23 | I19: =I22+I21 -> 140042.72 | J19: =J22+J21 -> 488637.07 | ... T19: =T22+T21 -> 2662420.7
B20: EBITDA Margin % | C20: =C19/C5 -> -0.39875696 | D20: =D19/D5 -> -0.44944194 | E20: =E19/E5 -> -1.246598 | F20: =F19/F5 -> -0.23423728 | G20: =G19/G5 -> -0.164 | H20: =H19/H5 -> -0.053 | I20: =I19/I5 -> 0.05 | J20: =J19/J5 -> 0.143 | ... T20: =T19/T5 -> 0.328
B21: Depreciation & Amortization | C21: 22366 | D21: 24305 | E21: 28868 | F21: 37115 | G21: =G5*G36 -> 45513.885 | H21: =H5*H36 -> 49295.038 | I21: =I5*I36 -> 56017.089 | J21: =J5*J36 -> 61506.764 | K21: =K5*K36 -> 73193.049 | L21: =L5*L36 -> 84903.937 | M21: =M5*M36 -> 95941.448 | N21: =N5*N36 -> 105535.59 | ... T21: =T5*T36 -> 146108.45
B22: EBIT (Operating Income) | C22: =C10-C17 -> -261548 | D22: =D10-D17 -> -306506 | E22: =E10-E17 -> -1134032 | F22: =F10-F17 -> -345416 | G22: =G10-G17 -> -332601.47 | H22: =H10-H17 -> -168051.27 | I22: =I10-I17 -> 84025.633 | J22: =J10-J17 -> 427130.3 | ... T22: =T10-T17 -> 2516312.2
B23: EBIT Margin % | C23: =C22/C5 -> -0.43604487 | D23: =D22/D5 -> -0.48815083 | E23: =E22/E5 -> -1.2791604 | F23: =F22/F5 -> -0.26243608 | G23: =G22/G5 -> -0.19 | H23: =H22/H5 -> -0.075 | I23: =I22/I5 -> 0.03 | J23: =J22/J5 -> 0.125 | ... T23: =T22/T5 -> 0.31
B24: Interest Income / (Expense), net | C24: -6569 | D24: -19079 | E24: -15900 | F24: 34930 | G24: =G5*G37 -> 43763.351 | H24: =H5*H37 -> 44813.671 | I24: =I5*I37 -> 44813.671 | J24: =J5*J37 -> 44421.552 | K24: =K5*K37 -> 48795.366 | L24: =L5*L37 -> 51885.739 | M24: =M5*M37 -> 53300.805 | N24: =N5*N37 -> 58630.885 | ... T24: =T5*T37 -> 81171.363
B25: Other Income Expense | C25: -1033 | D25: -1884 | E25: 1480 | F25: -15987 | G25: =G5*G38 -> -3501.0681 | H25: =H5*H38 -> -4481.3671 | I25: =I5*I38 -> -5601.7089 | J25: =J5*J38 -> -6834.0849 | K25: =K5*K38 -> -8132.561 | L25: =L5*L38 -> -9433.7707 | M25: =M5*M38 -> -10660.161 | N25: =N5*N38 -> -11726.177 | ... T25: =T5*T38 -> -16234.273
B26: EBT (Pre-tax Income) | C26: =C22+C24+C25 -> -269150 | D26: =D22+D24+D25 -> -327469 | E26: =E22+E24+E25 -> -1148452 | F26: =F22+F24+F25 -> -326473 | G26: =G22+G24+G25 -> -292339.18 | H26: =H22+H24+H25 -> -127718.96 | I26: =I22+I24+I25 -> 123237.6 | J26: =J22+J24+J25 -> 464717.77 | ... T26: =T22+T24+T25 -> 2581249.3
B27: Income Tax Expense | C27: 8596 | D27: 26689 | E27: 6368 | F27: 22355 | G27: =IF(G26>0,G26*G39,0) -> 0 | H27: =IF(H26>0,H26*H39,0) -> 0 | I27: =IF(I26>0,I26*I39,0) -> 22182.767 | J27: =IF(J26>0,J26*J39,0) -> 106885.09 | K27: =IF(K26>0,K26*K39,0) -> 182372.68 | L27: =IF(L26>0,L26*L39,0) -> 243013.93 | M27: =IF(M26>0,M26*M39,0) -> 304027.79 | N27: =IF(N26>0,N26*N39,0) -> 361400.78 | ... T27: =IF(T26>0,T26*T39,0) -> 593687.35
B28: Net Income / (Loss) | C28: =C26-C27 -> -277746 | D28: =D26-D27 -> -354158 | E28: =E26-E27 -> -1154820 | F28: =F26-F27 -> -348828 | G28: =G26-G27 -> -292339.18 | H28: =H26-H27 -> -127718.96 | I28: =I26-I27 -> 101054.83 | J28: =J26-J27 -> 357832.68 | ... T28: =T26-T27 -> 1987562
B29: Net Margin % | C29: =C28/C5 -> -0.46304969 | D29: =D28/D5 -> -0.56404286 | E29: =E28/E5 -> -1.3026088 | F29: =F28/F5 -> -0.2650284 | G29: =G28/G5 -> -0.167 | H29: =H28/H5 -> -0.057 | I29: =I28/I5 -> 0.03608 | J29: =J28/J5 -> 0.10472 | ... T29: =T28/T5 -> 0.24486
B31: PROJECTION ASSUMPTIONS
B32: Gross Margin % | C32: =C10/C5 -> 0.69655179 | D32: =D10/D5 -> 0.76912909 | E32: =E10/E5 -> 0.70024274 | F32: =F10/F5 -> 0.8010342 | G32: 0.8 | H32: 0.805 | I32: 0.81 | J32: 0.815 | K32: 0.82 | L32: 0.82 | M32: 0.82 | N32: 0.82 | O32: 0.82 | P32: 0.82 | Q32: 0.82 | R32: 0.82 | S32: 0.82 | T32: 0.82
B33: R&D as % of Revenue | C33: =C14/C5 -> 0.29184971 | D33: =D14/D5 -> 0.32892122 | E33: =E14/E5 -> 0.59964875 | F33: =F14/F5 -> 0.28391168 | G33: 0.32 | H33: 0.3 | I33: 0.28 | J33: 0.26 | K33: 0.24 | L33: 0.23 | M33: 0.225 | N33: 0.22 | O33: 0.215 | P33: 0.21 | Q33: 0.205 | R33: 0.205 | S33: 0.2 | T33: 0.2
B34: S&M as % of Revenue | C34: =C15/C5 -> 0.69611333 | D34: =D15/D5 -> 0.76849522 | E34: =E15/E5 -> 0.97853914 | F34: =F15/F5 -> 0.58427614 | G34: 0.55 | H34: 0.48 | I34: 0.4 | J34: 0.35 | K34: 0.32 | L34: 0.305 | M34: 0.29 | N34: 0.28 | O34: 0.27 | P34: 0.265 | Q34: 0.26 | R34: 0.255 | S34: 0.255 | T34: 0.25
B35: G&A as % of Revenue | C35: =C16/C5 -> 0.14463363 | D35: =D16/D5 -> 0.15986348 | E35: =E16/E5 -> 0.40121528 | F35: =F16/F5 -> 0.19528245 | G35: 0.12 | H35: 0.1 | I35: 0.1 | J35: 0.08 | K35: 0.075 | L35: 0.07 | M35: 0.065 | N35: 0.06 | O35: 0.06 | P35: 0.06 | Q35: 0.06 | R35: 0.06 | S35: 0.06 | T35: 0.06
B36: D&A as % of Revenue | C36: =C21/C5 -> 0.037287915 | D36: =D21/D5 -> 0.038708886 | E36: =E21/E5 -> 0.0325624 | F36: =F21/F5 -> 0.028198795 | G36: 0.026 | H36: 0.022 | I36: 0.02 | J36: 0.018 | K36: 0.018 | L36: 0.018 | M36: 0.018 | N36: 0.018 | O36: 0.018 | P36: 0.018 | Q36: 0.018 | R36: 0.018 | S36: 0.018 | T36: 0.018
B37: Interest Income / (Expense), net | C37: =C24/C5 -> -0.010951637 | D37: =D24/D5 -> -0.030385799 | E37: =E24/E5 -> -0.017934812 | F37: =F24/F5 -> 0.026538701 | G37: 0.025 | H37: 0.02 | I37: 0.016 | J37: 0.013 | K37: 0.012 | L37: 0.011 | M37: 0.01 | N37: 0.01 | O37: 0.01 | P37: 0.01 | Q37: 0.01 | R37: 0.01 | S37: 0.01 | T37: 0.01
B38: Other Income Expense | C38: =C25/C5 -> -0.0017221862 | D38: =D25/D5 -> -0.003000516 | E38: =E25/E5 -> 0.0016694039 | F38: =F25/F5 -> -0.012146413 | G38: -0.002 | H38: -0.002 | I38: -0.002 | J38: -0.002 | K38: -0.002 | L38: -0.002 | M38: -0.002 | N38: -0.002 | O38: -0.002 | P38: -0.002 | Q38: -0.002 | R38: -0.002 | S38: -0.002 | T38: -0.002
B39: Tax Rate | C39: 0 | D39: 0 | E39: 0 | F39: 0.1 | G39: 0 | H39: 0.1 | I39: 0.18 | J39: 0.23 | K39: 0.23 | L39: 0.23 | M39: 0.23 | N39: 0.23 | O39: 0.23 | P39: 0.23 | Q39: 0.23 | R39: 0.23 | S39: 0.23 | T39: 0.23
B40: Revenue Growth Rate | C40: __ | D40: =D5/C5-1 -> 0.046802452 | E40: =E5/D5-1 -> 0.41193708 | F40: 0.4845 | G40: 0.33 | H40: 0.28 | I40: 0.25 | J40: 0.22 | K40: 0.19 | L40: 0.16 | M40: 0.13 | N40: 0.1 | O40: 0.08 | P40: 0.07 | Q40: 0.06 | R40: 0.05 | S40: 0.04 | T40: 0.035

Sheet BS
B1: Balance Sheet ($000)
C2: FY2023 | D2: FY2024 | E2: FY2025 | F2: FY2026 | G2: FY2027E | H2: FY2028E | I2: FY2029E | J2: FY2030E | K2: FY2031E | L2: FY2032E | M2: FY2033E | N2: FY2034E | O2: FY2035E | P2: FY2036E | Q2: FY2037E | R2: FY2038E | S2: FY2039E | T2: FY2040E
B3: ASSETS
B4: Current Assets
B5: Cash & Equivalents & STI | C5: 295913 | D5: 279251 | E5: 705144 | F5: 1675775 | G5: =F5+CFS!G25 -> 2065307.8 | H5: =G5+CFS!H25 -> 2879540.1 | I5: =H5+CFS!I25 -> 4013435 | J5: =I5+CFS!J25 -> 5485823.6 | K5: =J5+CFS!K25 -> 7294153.3 | L5: =K5+CFS!L25 -> 9343643.7 | M5: =L5+CFS!M25 -> 11577393 | N5: =M5+CFS!N25 -> 13918423 | ... T5: =S5+CFS!T25 -> 30542695
B6: Accounts Receivable | C6: 155852 | D6: 139900 | E6: 182164 | F6: 260618 | G6: =IS!G4*G41/365 -> 345310.82 | H6: =IS!H4*H41/365 -> 441997.85 | I6: =IS!I4*I41/365 -> 552497.32 | J6: =IS!J4*J41/365 -> 674046.73 | K6: =IS!K4*K41/365 -> 802115.6 | L6: =IS!L4*L41/365 -> 930454.1 | M6: =IS!M4*M41/365 -> 1051413.1 | N6: =IS!N4*N41/365 -> 1156554.4 | ... T6: =IS!T4*T41/365 -> 1601188.5
B7: Inventory | C7: 9536 | D7: 4807 | E7: 4183 | F7: 5676 | G7: =IS!G9*BS!G45/365 -> 7673.5738 | H7: =IS!H9*BS!H45/365 -> 9576.6201 | I7: =IS!I9*BS!I45/365 -> 11663.832 | J7: =IS!J9*BS!J45/365 -> 13855.405 | K7: =IS!K9*BS!K45/365 -> 16042.312 | L7: =IS!L9*BS!L45/365 -> 18609.082 | M7: =IS!M9*BS!M45/365 -> 21028.263 | N7: =IS!N9*BS!N45/365 -> 23131.089 | ... T7: =IS!T9*BS!T45/365 -> 32023.77
B8: Prepaid Expenses | C8: 34690 | D8: 44721 | E8: 77857 | F8: 155901 | G8: =IS!G4*BS!G46 -> 201311.41 | H8: =IS!H4*BS!H46 -> 257678.61 | I8: =IS!I4*BS!I46 -> 322098.26 | J8: =IS!J4*BS!J46 -> 392959.88 | K8: =IS!K4*BS!K46 -> 467622.26 | L8: =IS!L4*BS!L46 -> 542441.82 | M8: =IS!M4*BS!M46 -> 612959.25 | N8: =IS!N4*BS!N46 -> 674255.18 | ... T8: =IS!T4*BS!T46 -> 933470.67
B9: Other Current Assets | C9: 68804 | D9: 80034 | E9: 108293 | F9: 125594 | G9: =G47*IS!G5 -> 166300.73 | H9: =H47*IS!H5 -> 212864.94 | I9: =I47*IS!I5 -> 266081.17 | J9: =J47*IS!J5 -> 324619.03 | K9: =K47*IS!K5 -> 386296.65 | L9: =L47*IS!L5 -> 448104.11 | M9: =M47*IS!M5 -> 506357.64 | N9: =N47*IS!N5 -> 556993.41 | ... T9: =T47*IS!T5 -> 771127.95
B10: Total Current Assets | C10: =SUM(C5:C9) -> 564795 | D10: =SUM(D5:D9) -> 548713 | E10: =SUM(E5:E9) -> 1077641 | F10: =SUM(F5:F9) -> 2223564 | G10: =SUM(G5:G9) -> 2785904.3 | H10: =SUM(H5:H9) -> 3801658.2 | I10: =SUM(I5:I9) -> 5165775.6 | J10: =SUM(J5:J9) -> 6891304.6 | ... T10: =SUM(T5:T9) -> 33880506
B11: Non-Current Assets
B12: Property & Equipment, net | C12: 83009 | D12: 77706 | E12: 79100 | F12: 116738 | G12: =F12+IS!G5*G42-IS!G21 -> 106234.8 | H12: =G12+IS!H5*H42-IS!H21 -> 101753.43 | I12: =H12+IS!I5*I42-IS!I21 -> 101753.43 | J12: =I12+IS!J5*J42-IS!J21 -> 108587.51 | K12: =J12+IS!K5*K42-IS!K21 -> 116720.07 | L12: =K12+IS!L5*L42-IS!L21 -> 126153.85 | M12: =L12+IS!M5*M42-IS!M21 -> 136814.01 | N12: =M12+IS!N5*N42-IS!N21 -> 148540.18 | ... T12: =S12+IS!T5*T42-IS!T21 -> 236120.61
B13: Goodwill & Intangibles | C13: 4236 | D13: 100343 | E13: 100343 | F13: 199606 | G13: =F13 -> 199606 | H13: =G13 -> 199606 | I13: =H13 -> 199606 | J13: =I13 -> 199606 | K13: =J13 -> 199606 | L13: =K13 -> 199606 | M13: =L13 -> 199606 | N13: =M13 -> 199606 | ... T13: =S13 -> 199606
B14: Accounts Receivable Long term | C14: 4900 | D14: 2600 | E14: 4000 | F14: 8800 | G14: =F14 -> 8800 | H14: =G14 -> 8800 | I14: =H14 -> 8800 | J14: =I14 -> 8800 | K14: =J14 -> 8800 | L14: =K14 -> 8800 | M14: =L14 -> 8800 | N14: =M14 -> 8800 | ... T14: =S14 -> 8800
B15: Deferred Charges, LT | C15: 100729 | D15: 113814 | E15: 132465 | F15: 157592 | G15: =F15 -> 157592 | H15: =G15 -> 157592 | I15: =H15 -> 157592 | J15: =I15 -> 157592 | K15: =J15 -> 157592 | L15: =K15 -> 157592 | M15: =L15 -> 157592 | N15: =M15 -> 157592 | ... T15: =S15 -> 157592
B16: Other Non-Current Assets | C16: 11514 | D16: 30434 | E16: 29425 | F16: 60236 | G16: =F16 -> 60236 | H16: =G16 -> 60236 | I16: =H16 -> 60236 | J16: =I16 -> 60236 | K16: =J16 -> 60236 | L16: =K16 -> 60236 | M16: =L16 -> 60236 | N16: =M16 -> 60236 | ... T16: =S16 -> 60236
B17: Total Non-Current Assets | C17: =SUM(C12:C16) -> 204388 | D17: =SUM(D12:D16) -> 324897 | E17: =SUM(E12:E16) -> 345333 | F17: =SUM(F12:F16) -> 542972 | G17: =SUM(G12:G16) -> 532468.8 | H17: =SUM(H12:H16) -> 527987.43 | I17: =SUM(I12:I16) -> 527987.43 | J17: =SUM(J12:J16) -> 534821.51 | ... T17: =SUM(T12:T16) -> 662354.61
B18: TOTAL ASSETS | C18: =C10+C17 -> 769183 | D18: =D10+D17 -> 873610 | E18: =E10+E17 -> 1422974 | F18: =F10+F17 -> 2766536 | G18: =G10+G17 -> 3318373.1 | H18: =H10+H17 -> 4329645.6 | I18: =I10+I17 -> 5693763 | J18: =J10+J17 -> 7426126.1 | ... T18: =T10+T17 -> 34542861
B20: LIABILITIES
B21: Current Liabilities
B22: Accounts Payable | C22: 8085 | D22: 6867 | E22: 10439 | F22: 15329 | G22: =G48*IS!G9/365 -> 20143.131 | H22: =H48*IS!H9/365 -> 25138.628 | I22: =I48*IS!I9/365 -> 30617.56 | J22: =J48*IS!J9/365 -> 36370.438 | K22: =K48*IS!K9/365 -> 42111.069 | L22: =L48*IS!L9/365 -> 48848.84 | M22: =M48*IS!M9/365 -> 55199.189 | N22: =N48*IS!N9/365 -> 60719.108 | ... T22: =T48*IS!T9/365 -> 84062.398
B23: Deferred Revenue (Current) | C23: 315954 | D23: 526480 | E23: 777135 | F23: 1068754 | G23: =IS!G5*G43 -> 1260384.5 | H23: =IS!H5*H43 -> 1613292.2 | I23: =IS!I5*I43 -> 2016615.2 | J23: =IS!J5*J43 -> 2460270.5 | K23: =IS!K5*K43 -> 2927722 | L23: =IS!L5*L43 -> 3396157.5 | M23: =IS!M5*M43 -> 3837657.9 | N23: =IS!N5*N43 -> 4221423.7 | ... T23: =IS!T5*T43 -> 5844338.1
B24: Accrued & Other Current Liabilities | C24: 111365 | D24: 122934 | E24: 162602 | F24: 229976 | G24: =G49*IS!G5 -> 306343.46 | H24: =H49*IS!H5 -> 392119.62 | I24: =I49*IS!I5 -> 490149.53 | J24: =J49*IS!J5 -> 597982.42 | K24: =K49*IS!K5 -> 711599.09 | L24: =L49*IS!L5 -> 825454.94 | M24: =M49*IS!M5 -> 932764.08 | N24: =N49*IS!N5 -> 1026040.5 | ... T24: =T49*IS!T5 -> 1420498.8
B25: Total Current Liabilities | C25: =SUM(C22:C24) -> 435404 | D25: =SUM(D22:D24) -> 656281 | E25: =SUM(E22:E24) -> 950176 | F25: =SUM(F22:F24) -> 1314059 | G25: =SUM(G22:G24) -> 1586871.1 | H25: =SUM(H22:H24) -> 2030550.4 | I25: =SUM(I22:I24) -> 2537382.3 | J25: =SUM(J22:J24) -> 3094623.4 | ... T25: =SUM(T22:T24) -> 7348899.4
B26: Non-Current Liabilities
B27: Long-Term Debt | C27: 179699 | D27: 287042 | E27: 322341 | F27: 1130721 | G27: =F27 -> 1130721 | H27: =G27 -> 1130721 | I27: =H27 -> 1130721 | J27: =I27 -> 1130721 | K27: =J27 -> 1130721 | L27: =K27 -> 1130721 | M27: =L27 -> 1130721 | N27: =M27 -> 1130721 | ... T27: =S27 -> 1130721
B28: Deferred Revenue (LT) | C28: 490279 | D28: 579781 | E28: 642370 | F28: 776547 | G28: =G44*IS!G5 -> 962793.72 | H28: =H44*IS!H5 -> 1232376 | I28: =I44*IS!I5 -> 1540469.9 | J28: =J44*IS!J5 -> 1879373.3 | K28: =K44*IS!K5 -> 2236454.3 | L28: =L44*IS!L5 -> 2594287 | M28: =M44*IS!M5 -> 2931544.3 | N28: =N44*IS!N5 -> 3224698.7 | ... T28: =T44*IS!T5 -> 4464424.9
B29: Other Non-Current Liabilities | C29: 36417 | D29: 55050 | E29: 61821 | F29: 64771 | G29: =F29 -> 64771 | H29: =G29 -> 64771 | I29: =H29 -> 64771 | J29: =I29 -> 64771 | K29: =J29 -> 64771 | L29: =K29 -> 64771 | M29: =L29 -> 64771 | N29: =M29 -> 64771 | ... T29: =S29 -> 64771
B30: Total Non-Current Liabilities | C30: =SUM(C27:C29) -> 706395 | D30: =SUM(D27:D29) -> 921873 | E30: =SUM(E27:E29) -> 1026532 | F30: =SUM(F27:F29) -> 1972039 | G30: =SUM(G27:G29) -> 2158285.7 | H30: =SUM(H27:H29) -> 2427868 | I30: =SUM(I27:I29) -> 2735961.9 | J30: =SUM(J27:J29) -> 3074865.3 | ... T30: =SUM(T27:T29) -> 5659916.9
B31: TOTAL LIABILITIES | C31: =C25+C30 -> 1141799 | D31: =D25+D30 -> 1578154 | E31: =E25+E30 -> 1976708 | F31: =F25+F30 -> 3286098 | G31: =G25+G30 -> 3745156.8 | H31: =H25+H30 -> 4458418.4 | I31: =I25+I30 -> 5273344.2 | J31: =J25+J30 -> 6169488.7 | ... T31: =T25+T30 -> 13008816
B33: STOCKHOLDERS' EQUITY (DEFICIT)
B34: Common Stock & APIC | C34: 955739 | D34: 977969 | E34: 2283599 | F34: 2666599 | G34: =F34+CFS!G6+CFS!G21 -> 3051716.5 | H34: =G34+CFS!H6+CFS!H21 -> 3477446.4 | I34: =H34+CFS!I6+CFS!I21 -> 3925583.1 | J34: =I34+CFS!J6+CFS!J21 -> 4403969 | K34: =J34+CFS!K6+CFS!K21 -> 4932585.5 | L34: =K34+CFS!L6+CFS!L21 -> 5498611.7 | M34: =L34+CFS!M6+CFS!M21 -> 6084920.6 | N34: =M34+CFS!N6+CFS!N21 -> 6671229.4 | ... T34: =S34+CFS!T6+CFS!T21 -> 10779333
B35: Accumulated Deficit | C35: -1328355 | D35: -1682513 | E35: -2837333 | F35: -3186161 | G35: =F35+IS!G28 -> -3478500.2 | H35: =G35+IS!H28 -> -3606219.1 | I35: =H35+IS!I28 -> -3505164.3 | J35: =I35+IS!J28 -> -3147331.6 | K35: =J35+IS!K28 -> -2536779.6 | L35: =K35+IS!L28 -> -1723211.2 | M35: =L35+IS!M28 -> -705379.07 | N35: =M35+IS!N28 -> 504527.88 | ... T35: =S35+IS!T28 -> 10754711
B36: Total Stockholders' Equity (Deficit) | C36: =C34+C35 -> -372616 | D36: =D34+D35 -> -704544 | E36: =E34+E35 -> -553734 | F36: =F34+F35 -> -519562 | G36: =G34+G35 -> -426783.7 | H36: =H34+H35 -> -128772.78 | I36: =I34+I35 -> 420418.76 | J36: =J34+J35 -> 1256637.4 | ... T36: =T34+T35 -> 21534044
B37: TOTAL LIABILITIES & EQUITY | C37: =C31+C36 -> 769183 | D37: =D31+D36 -> 873610 | E37: =E31+E36 -> 1422974 | F37: =F31+F36 -> 2766536 | G37: =G31+G36 -> 3318373.1 | H37: =H31+H36 -> 4329645.6 | I37: =I31+I36 -> 5693763 | J37: =J31+J36 -> 7426126.1 | ... T37: =T31+T36 -> 34542861
B38: Balance Check (Assets - L&E) | C38: =C18-C37 -> 0 | D38: =D18-D37 -> 0 | E38: =E18-E37 -> 0 | F38: =F18-F37 -> 0 | G38: =G18-G37 -> 0 | H38: =H18-H37 -> 0 | I38: =I18-I37 -> 0 | J38: =J18-J37 -> 0 | ... T38: =T18-T37 -> 0
B40: BALANCE SHEET ASSUMPTIONS
B41: AR - Days Sales Outstanding (days) | C41: =C6/IS!C5*365 -> 94.838576 | D41: =D6/IS!D5*365 -> 81.325292 | E41: =E6/IS!E5*365 -> 74.99894 | F41: =F6/IS!F5*365 -> 72.273378 | G41: 72 | H41: 72 | I41: 72 | J41: 72 | K41: 72 | L41: 72 | M41: 72 | N41: 72 | O41: 72 | P41: 72 | Q41: 72 | R41: 72 | S41: 72 | T41: 72
B42: CapEx as % of Revenue | C42: =-CFS!C13/IS!C5 -> 0.041707582 | D42: =-CFS!D13/IS!D5 -> 0.019641913 | E42: =-CFS!E13/IS!E5 -> 0.019045868 | F42: =-CFS!F13/IS!F5 -> 0.02251269 | G42: 0.02 | H42: 0.02 | I42: 0.02 | J42: 0.02 | K42: 0.02 | L42: 0.02 | M42: 0.02 | N42: 0.02 | O42: 0.02 | P42: 0.02 | Q42: 0.02 | R42: 0.02 | S42: 0.02 | T42: 0.02
B43: Deferred Revenue (Current) % of Rev | C43: =C23/IS!C5 -> 0.5267489 | D43: =D23/IS!D5 -> 0.83848815 | E43: =E23/IS!E5 -> 0.87658932 | F43: =F23/IS!F5 -> 0.81200525 | G43: 0.72 | H43: 0.72 | I43: 0.72 | J43: 0.72 | K43: 0.72 | L43: 0.72 | M43: 0.72 | N43: 0.72 | O43: 0.72 | P43: 0.72 | Q43: 0.72 | R43: 0.72 | S43: 0.72 | T43: 0.72
...

Sheet CFS
B1: Cash Flow Statement ($000)
C2: FY2023 | D2: FY2024 | E2: FY2025 | F2: FY2026 | G2: FY2027E | H2: FY2028E | I2: FY2029E | J2: FY2030E | K2: FY2031E | L2: FY2032E | M2: FY2033E | N2: FY2034E | O2: FY2035E | P2: FY2036E | Q2: FY2037E | R2: FY2038E | S2: FY2039E | T2: FY2040E
B3: OPERATING ACTIVITIES
B4: Net Income / (Loss) | C4: =IS!C28 -> -277746 | D4: =IS!D28 -> -354158 | E4: =IS!E28 -> -1154820 | F4: =IS!F28 -> -348828 | G4: =IS!G28 -> -292339.18 | H4: =IS!H28 -> -127718.96 | I4: =IS!I28 -> 101054.83 | J4: =IS!J28 -> 357832.68 | ... T4: =IS!T28 -> 1987562
B5: Depreciation & Amortization | C5: =IS!C21 -> 22366 | D5: =IS!D21 -> 24305 | E5: =IS!E21 -> 28868 | F5: =IS!F21 -> 37115 | G5: =IS!G21 -> 45513.885 | H5: =IS!H21 -> 49295.038 | I5: =IS!I21 -> 56017.089 | J5: =IS!J21 -> 61506.764 | ... T5: =IS!T21 -> 146108.45
B6: Stockbased Compensation | C6: 6954 | D6: 5715 | E6: 913913 | F6: 329374 | G6: =IS!G5*BS!G50 -> 385117.49 | H6: =IS!H5*BS!H50 -> 425729.88 | I6: =IS!I5*BS!I50 -> 448136.71 | J6: =IS!J5*BS!J50 -> 478385.94 | K6: =IS!K5*BS!K50 -> 528616.46 | L6: =IS!L5*BS!L50 -> 566026.24 | M6: =IS!M5*BS!M50 -> 586308.85 | N6: =IS!N5*BS!N50 -> 586308.85 | ... T6: =IS!T5*BS!T50 -> 730542.26
B7: Other Non-Cash Items | C7: 93205 | D7: 85748 | E7: 118551 | F7: 117070 | G7: 0 | H7: 0 | I7: 0 | J7: 0 | K7: 0 | L7: 0 | M7: 0 | N7: 0 | O7: 0 | P7: 0 | Q7: 0 | R7: 0 | S7: 0 | T7: 0
B8: Change in Deferred Revenue | C8: 338819 | D8: 299752 | E8: 313244 | F8: 425796 | G8: =(BS!G28+BS!G23)-(BS!F28+BS!F23) -> 377877.22 | H8: =(BS!H28+BS!H23)-(BS!G28+BS!G23) -> 622489.9 | I8: =(BS!I28+BS!I23)-(BS!H28+BS!H23) -> 711417.03 | J8: =(BS!J28+BS!J23)-(BS!I28+BS!I23) -> 782558.73 | K8: =(BS!K28+BS!K23)-(BS!J28+BS!J23) -> 824532.34 | L8: =(BS!L28+BS!L23)-(BS!K28+BS!K23) -> 826268.2 | M8: =(BS!M28+BS!M23)-(BS!L28+BS!L23) -> 778757.77 | N8: =(BS!N28+BS!N23)-(BS!M28+BS!M23) -> 676920.22 | ... T8: =(BS!T28+BS!T23)-(BS!S28+BS!S23) -> 348605.51
B9: Change in Other Net Working Capital | C9: -164311 | D9: -65880 | E9: -171528 | F9: -277619 | G9: =-(BS!G6-BS!F6)-(BS!G7-BS!F7)-(BS!G8-BS!F8)-(BS!G9-BS!F9)+(BS!G22-BS!F22)+(BS!G24-BS!F24) -> -91625.956 | H9: =-(BS!H6-BS!G6)-(BS!H7-BS!G7)-(BS!H8-BS!G8)-(BS!H9-BS!G9)+(BS!H22-BS!G22)+(BS!H24-BS!G24) -> -110749.81 | I9: =-(BS!I6-BS!H6)-(BS!I7-BS!H7)-(BS!I8-BS!H8)-(BS!I9-BS!H9)+(BS!I22-BS!H22)+(BS!I24-BS!H24) -> -126713.72 | J9: =-(BS!J6-BS!I6)-(BS!J7-BS!I7)-(BS!J8-BS!I8)-(BS!J9-BS!I9)+(BS!J22-BS!I22)+(BS!J24-BS!I24) -> -139554.68 | K9: =-(BS!K6-BS!J6)-(BS!K7-BS!J7)-(BS!K8-BS!J8)-(BS!K9-BS!J9)+(BS!K22-BS!J22)+(BS!K24-BS!J24) -> -147238.49 | L9: =-(BS!L6-BS!K6)-(BS!L7-BS!K7)-(BS!L8-BS!K8)-(BS!L9-BS!K9)+(BS!L22-BS!K22)+(BS!L24-BS!K24) -> -146938.67 | M9: =-(BS!M6-BS!L6)-(BS!M7-BS!L7)-(BS!M8-BS!L8)-(BS!M9-BS!L9)+(BS!M22-BS!L22)+(BS!M24-BS!L24) -> -138489.69 | N9: =-(BS!N6-BS!M6)-(BS!N7-BS!M7)-(BS!N8-BS!M8)-(BS!N9-BS!M9)+(BS!N22-BS!M22)+(BS!N24-BS!M24) -> -120379.5 | ... T9: =-(BS!T6-BS!S6)-(BS!T7-BS!S7)-(BS!T8-BS!S8)-(BS!T9-BS!S9)+(BS!T22-BS!S22)+(BS!T24-BS!S24) -> -61993.95
B10: Cash from Operations | C10: =SUM(C4:C9) -> 19287 | D10: =SUM(D4:D9) -> -4518 | E10: =SUM(E4:E9) -> 48228 | F10: =SUM(F4:F9) -> 282908 | G10: =SUM(G4:G9) -> 424543.45 | H10: =SUM(H4:H9) -> 859046.04 | I10: =SUM(I4:I9) -> 1189911.9 | J10: =SUM(J4:J9) -> 1540729.4 | ... T10: =SUM(T4:T9) -> 3150824.3
B12: INVESTING ACTIVITIES
B13: Capital Expenditures | C13: -25017 | D13: -12333 | E13: -16885 | F13: -29631 | G13: =-IS!G5*BS!G42 -> -35010.681 | H13: =-IS!H5*BS!H42 -> -44813.671 | I13: =-IS!I5*BS!I42 -> -56017.089 | J13: =-IS!J5*BS!J42 -> -68340.849 | K13: =-IS!K5*BS!K42 -> -81325.61 | L13: =-IS!L5*BS!L42 -> -94337.707 | M13: =-IS!M5*BS!M42 -> -106601.61 | N13: =-IS!N5*BS!N42 -> -117261.77 | ... T13: =-IS!T5*BS!T42 -> -162342.73
B14: Cash Acqusitions | D14: -90328 | F14: -21259 | G14: 0 | H14: 0 | I14: 0 | J14: 0 | K14: 0 | L14: 0 | M14: 0 | N14: 0 | O14: 0 | P14: 0 | Q14: 0 | R14: 0 | S14: 0 | T14: 0
B15: Purchase of Investments | C15: -9281 | D15: -7675 | E15: -9714 | F15: -15437 | G15: 0 | H15: 0 | I15: 0 | J15: 0 | K15: 0 | L15: 0 | M15: 0 | N15: 0 | O15: 0 | P15: 0 | Q15: 0 | R15: 0 | S15: 0 | T15: 0
B16: Investment in Marketable & Equity Securities | C16: -90890 | D16: 16713 | E16: -356843 | F16: -763762 | G16: 0 | H16: 0 | I16: 0 | J16: 0 | K16: 0 | L16: 0 | M16: 0 | N16: 0 | O16: 0 | P16: 0 | Q16: 0 | R16: 0 | S16: 0 | T16: 0
B17: Cash from Investing | C17: =SUM(C13:C16) -> -125188 | D17: =SUM(D13:D16) -> -93623 | E17: =SUM(E13:E16) -> -383442 | F17: =SUM(F13:F16) -> -830089 | G17: =SUM(G13:G16) -> -35010.681 | H17: =SUM(H13:H16) -> -44813.671 | I17: =SUM(I13:I16) -> -56017.089 | J17: =SUM(J13:J16) -> -68340.849 | ... T17: =SUM(T13:T16) -> -162342.73
B19: FINANCING ACTIVITIES
B20: Net Debt Issuance / (Repayment) | C20: 171463 | D20: 96525 | E20: 0 | F20: 800229 | G20: 0 | H20: 0 | I20: 0 | J20: 0 | K20: 0 | L20: 0 | M20: 0 | N20: 0 | O20: 0 | P20: 0 | Q20: 0 | R20: 0 | S20: 0 | T20: 0
B21: Net Equity Activity (Issuance less Repurchase, incl. Pref.) | C21: 3810 | D21: 3383 | E21: 402276 | F21: 26725 | G21: 0 | H21: 0 | I21: 0 | J21: 0 | K21: 0 | L21: 0 | M21: 0 | N21: 0 | O21: 0 | P21: 0 | Q21: 0 | R21: 0 | S21: 0 | T21: 0
B22: Other Financing Activities | C22: -3450 | D22: -3959 | E22: -4253 | F22: -90453 | G22: 0 | H22: 0 | I22: 0 | J22: 0 | K22: 0 | L22: 0 | M22: 0 | N22: 0 | O22: 0 | P22: 0 | Q22: 0 | R22: 0 | S22: 0 | T22: 0
B23: Cash from Financing | C23: =SUM(C20:C22) -> 171823 | D23: =SUM(D20:D22) -> 95949 | E23: =SUM(E20:E22) -> 398023 | F23: =SUM(F20:F22) -> 736501 | G23: =SUM(G20:G22) -> 0 | H23: =SUM(H20:H22) -> 0 | I23: =SUM(I20:I22) -> 0 | J23: =SUM(J20:J22) -> 0 | ... T23: =SUM(T20:T22) -> 0
B24: Foreign Exchange Rate Adj. | C24: -1009 | D24: -1355 | E24: -6274 | F24: 9826 | G24: 0 | H24: 0 | I24: 0 | J24: 0 | K24: 0 | L24: 0 | M24: 0 | N24: 0 | O24: 0 | P24: 0 | Q24: 0 | R24: 0 | S24: 0 | T24: 0
B25: Net Cash Flow | C25: =C24+C10+C17+C23 -> 64913 | D25: =D24+D10+D17+D23 -> -3547 | E25: =E24+E10+E17+E23 -> 56535 | F25: =F24+F10+F17+F23 -> 199146 | G25: =G24+G10+G17+G23 -> 389532.77 | H25: =H24+H10+H17+H23 -> 814232.37 | I25: =I24+I10+I17+I23 -> 1133894.8 | J25: =J24+J10+J17+J23 -> 1472388.6 | ... T25: =T24+T10+T17+T23 -> 2988481.5

Sheet WACC
B1: WEIGHTED AVERAGE COST OF CAPITAL
B3: COST OF EQUITY (CAPM)
B4: Risk-Free Rate (10-Yr Treasury) | C4: 0.0446 | E4: Source: FRED
B5: Equity Risk Premium | C5: 0.0423 | E5: Damodaran implied ERP, Jan 2026 (same annual dataset as the unlevered beta)
B6: Levered Beta | C6: =1.23*(1+(1-C11)*C18/C17) -> 1.3088617 | E6: βL = βu × (1 + (1 − t) × D/E) Using Damodaran's Unlevered Beta for the Software Industry
B7: Cost of Equity | C7: =C4+C6*C5 -> 0.099964851
B9: COST OF DEBT
B10: Pre-Tax Cost of Debt | C10: 0.0725 | E10: risk-free + credit spread; RBRK notes are 0% YTM so their YTM is not meaningful)
B11: Marginal Tax Rate | C11: =IS!J39 -> 0.23
B12: After-Tax Cost of Debt | C12: =C10*(1-C11) -> 0.055825
B14: CAPITAL STRUCTURE
B15: Current Share Price | C15: 60.47 | E15: (close, 05/12/2026 - Yahoo Finance)
B16: Diluted Shares Outstanding (000) | C16: =C33 -> 228395.42 | E16: (see Diluted Share Build below)
B17: Market Value of Equity | C17: =C15*C16 -> 13811071
B18: Market Value of Debt | C18: 1150000
B19: Total Capitalization | C19: =C17+C18 -> 14961071
B20: Weight of Equity (E / V) | C20: =C17/C19 -> 0.92313385
B21: Weight of Debt (D / V) | C21: =C18/C19 -> 0.076866154
B23: WACC
B24: WACC | C24: =C20*C7+C21*C12 -> 0.096571991
B26: DILUTED SHARE BUILD (000) - FY2026 10-K
B27: Class A Shares Outstanding | C27: 157404.65 | E27: (10-K cover, as of 2/28/2026)
B28: Class B Shares Outstanding | C28: 44871.492 | E28: (10-K cover, as of 2/28/2026)
B29: Stock Options Outstanding | C29: 8970.353 | E29: (as of 1/31/2026)
B30: Option Exercise Price (W.Avg) | C30: 29.2 | E30: (as of 1/31/2026)
B31: Options - Net Shares (TSM) | C31: =IF(C15>C30,C29*(1-C30/C15),0) -> 4638.7124 | E31: (treasury stock method at current share price)
B32: Unvested RSUs | C32: 21480.571 | E32: (as of 1/31/2026; convertible notes excluded because conversion ~$125 > share price)
B33: Fully Diluted Shares | C33: =C27+C28+C31+C32 -> 228395.42

Sheet DCF
B1: DISCOUNTED CASH FLOW ANALYSIS ($000 except per-share)
G2: =IS!G2 -> FY2027E | H2: =IS!H2 -> FY2028E | I2: =IS!I2 -> FY2029E | J2: =IS!J2 -> FY2030E | K2: =IS!K2 -> FY2031E | L2: =IS!L2 -> FY2032E | M2: =IS!M2 -> FY2033E | N2: =IS!N2 -> FY2034E | ... T2: =IS!T2 -> FY2040E
B3: UNLEVERED FREE CASH FLOW
B4: Revenue | G4: =IS!G5 -> 1750534 | H4: =IS!H5 -> 2240683.6 | I4: =IS!I5 -> 2800854.4 | J4: =IS!J5 -> 3417042.4 | K4: =IS!K5 -> 4066280.5 | L4: =IS!L5 -> 4716885.4 | M4: =IS!M5 -> 5330080.5 | N4: =IS!N5 -> 5863088.5 | ... T4: =IS!T5 -> 8117136.3
B5: EBIT | G5: =IS!G22 -> -332601.47 | H5: =IS!H22 -> -168051.27 | I5: =IS!I22 -> 84025.633 | J5: =IS!J22 -> 427130.3 | K5: =IS!K22 -> 752261.89 | L5: =IS!L22 -> 1014130.4 | M5: =IS!M22 -> 1279219.3 | N5: =IS!N22 -> 1524403 | ... T5: =IS!T22 -> 2516312.2
B6: Tax Rate | G6: =IS!G39 -> 0 | H6: =IS!H39 -> 0.1 | I6: =IS!I39 -> 0.18 | J6: =IS!J39 -> 0.23 | K6: =IS!K39 -> 0.23 | L6: =IS!L39 -> 0.23 | M6: =IS!M39 -> 0.23 | N6: =IS!N39 -> 0.23 | ... T6: =IS!T39 -> 0.23
B7: Less: Taxes on EBIT | G7: =-IF(G5>0,G5*G6,0) -> 0 | H7: =-IF(H5>0,H5*H6,0) -> 0 | I7: =-IF(I5>0,I5*I6,0) -> -15124.614 | J7: =-IF(J5>0,J5*J6,0) -> -98239.97 | K7: =-IF(K5>0,K5*K6,0) -> -173020.23 | L7: =-IF(L5>0,L5*L6,0) -> -233249.98 | M7: =-IF(M5>0,M5*M6,0) -> -294220.44 | N7: =-IF(N5>0,N5*N6,0) -> -350612.69 | ... T7: =-IF(T5>0,T5*T6,0) -> -578751.82
B8: NOPAT | G8: =G5+G7 -> -332601.47 | H8: =H5+H7 -> -168051.27 | I8: =I5+I7 -> 68901.019 | J8: =J5+J7 -> 328890.33 | K8: =K5+K7 -> 579241.66 | L8: =L5+L7 -> 780880.37 | M8: =M5+M7 -> 984998.87 | N8: =N5+N7 -> 1173790.3 | ... T8: =T5+T7 -> 1937560.4
B9: Plus: D&A | G9: =IS!G21 -> 45513.885 | H9: =IS!H21 -> 49295.038 | I9: =IS!I21 -> 56017.089 | J9: =IS!J21 -> 61506.764 | K9: =IS!K21 -> 73193.049 | L9: =IS!L21 -> 84903.937 | M9: =IS!M21 -> 95941.448 | N9: =IS!N21 -> 105535.59 | ... T9: =IS!T21 -> 146108.45
B10: Less: CapEx (% of Revenue) | G10: =BS!G42 -> 0.02 | H10: =BS!H42 -> 0.02 | I10: =BS!I42 -> 0.02 | J10: =BS!J42 -> 0.02 | K10: =BS!K42 -> 0.02 | L10: =BS!L42 -> 0.02 | M10: =BS!M42 -> 0.02 | N10: =BS!N42 -> 0.02 | ... T10: =BS!T42 -> 0.02
B11: Less: CapEx | G11: =-G4*G10 -> -35010.681 | H11: =-H4*H10 -> -44813.671 | I11: =-I4*I10 -> -56017.089 | J11: =-J4*J10 -> -68340.849 | K11: =-K4*K10 -> -81325.61 | L11: =-L4*L10 -> -94337.707 | M11: =-M4*M10 -> -106601.61 | N11: =-N4*N10 -> -117261.77 | ... T11: =-T4*T10 -> -162342.73
B12: Change in NWC (% of Revenue) | G12: =G13/G4 -> 0.16352225 | H12: =H13/H4 -> 0.2283857 | I12: =I13/I4 -> 0.2087589 | J12: =J13/J4 -> 0.18817561 | K12: =K13/K4 -> 0.16656349 | L12: =L13/L4 -> 0.14402078 | M12: =M13/M4 -> 0.12012353 | N12: =N13/N4 -> 0.09492279 | ... T12: =T13/T4 -> 0.035309443
B13: Plus / (Less): Change in NWC | G13: =CFS!G8+CFS!G9 -> 286251.26 | H13: =CFS!H8+CFS!H9 -> 511740.09 | I13: =CFS!I8+CFS!I9 -> 584703.31 | J13: =CFS!J8+CFS!J9 -> 643004.05 | K13: =CFS!K8+CFS!K9 -> 677293.85 | L13: =CFS!L8+CFS!L9 -> 679329.53 | M13: =CFS!M8+CFS!M9 -> 640268.08 | N13: =CFS!N8+CFS!N9 -> 556540.72 | ... T13: =CFS!T8+CFS!T9 -> 286611.56
B14: Unlevered Free Cash Flow | G14: =G8+G9+G11+G13 -> -35846.999 | H14: =H8+H9+H11+H13 -> 348170.19 | I14: =I8+I9+I11+I13 -> 653604.32 | J14: =J8+J9+J11+J13 -> 965060.3 | K14: =K8+K9+K11+K13 -> 1248402.9 | L14: =L8+L9+L11+L13 -> 1450776.1 | M14: =M8+M9+M11+M13 -> 1614606.8 | N14: =N8+N9+N11+N13 -> 1718604.9 | ... T14: =T8+T9+T11+T13 -> 2207937.7
B16: DISCOUNTING
B17: Discount Period | G17: 1 | H17: 2 | I17: 3 | J17: 4 | K17: 5 | L17: 6 | M17: 7 | N17: 8 | O17: 9 | P17: 10 | Q17: 11 | R17: 12 | S17: 13 | T17: 14
B18: Discount Factor | G18: =1/(1+WACC!$C$24)^G17 -> 0.91193283 | H18: =1/(1+WACC!$C$24)^H17 -> 0.83162149 | I18: =1/(1+WACC!$C$24)^I17 -> 0.75838294 | J18: =1/(1+WACC!$C$24)^J17 -> 0.6915943 | K18: =1/(1+WACC!$C$24)^K17 -> 0.63068755 | L18: =1/(1+WACC!$C$24)^L17 -> 0.57514468 | M18: =1/(1+WACC!$C$24)^M17 -> 0.52449332 | N18: =1/(1+WACC!$C$24)^N17 -> 0.47830268 | ... T18: =1/(1+WACC!$C$24)^T17 -> 0.27509324
B19: PV of Unlevered FCF | G19: =G14*G18 -> -32690.056 | H19: =H14*H18 -> 289545.81 | I19: =I14*I18 -> 495682.37 | J19: =J14*J18 -> 667430.2 | K19: =K14*K18 -> 787352.19 | L19: =L14*L18 -> 834406.18 | M19: =M14*M18 -> 846850.47 | N19: =N14*N18 -> 822013.3 | ... T19: =T14*T18 -> 607388.74
B21: TERMINAL VALUE & VALUATION BRIDGE
C22: Perpetuity Growth Method | E22: Exit Multiple Method
B23: Sum of PV of Explicit FCFs | C23: =SUM(G19:T19) -> 8962724.6 | E23: =C23 -> 8962724.6
B24: Terminal Year Unlevered FCF | C24: =T14 -> 2207937.7
B25: Terminal Growth Rate | C25: 0.025 | G25: (below long-run US nominal GDP growth)
B26: Terminal Value | C26: =C24*(1+C25)/(WACC!$C$24-C25) -> 31620417
B27: PV of Terminal Value | C27: =C26/(1+WACC!$C$24)^T17 -> 8698562.9
B28: Terminal Year EBITDA | E28: =IS!T19 -> 2662420.7
B29: Exit EV / EBITDA Multiple | E29: 11 | G29: (assumed exit multiple for mature security software)
B30: Terminal Value | E30: =E28*E29 -> 29286628
B31: PV of Terminal Value | E31: =E30/(1+WACC!$C$24)^T17 -> 8056553.3
B32: Implied Enterprise Value | C32: =C23+C27 -> 17661287 | E32: =E23+E31 -> 17019278
B33: Less: Total Debt | C33: =-WACC!$C$18 -> -1150000 | E33: =-WACC!$C$18 -> -1150000
B34: Plus: Cash & Equivalents | C34: =BS!F5 -> 1675775 | E34: =BS!F5 -> 1675775 | G34: (cash + ST investments at 1/31/2026)
B35: Less: Preferred Stock | C35: 0 | E35: 0
B36: Less: Minority Interest | C36: 0 | E36: 0
B37: Implied Equity Value | C37: =C32+C33+C34-C35-C36 -> 18187062 | E37: =E32+E33+E34-E35-E36 -> 17545053
B38: Diluted Shares Outstanding (000) | C38: =WACC!$C$16 -> 228395.42 | E38: =WACC!$C$16 -> 228395.42
B39: Implied Share Price | C39: =C37/C38 -> 79.629715 | E39: =E37/E38 -> 76.818758
B40: Current Share Price | C40: =WACC!$C$15 -> 60.47 | E40: =WACC!$C$15 -> 60.47
B41: Implied Upside / (Downside) | C41: =C39/C40-1 -> 0.31684661 | E41: =E39/E40-1 -> 0.27036148
B43: CROSS-CHECKS
...
